<robot name="differential_bot_with_camera" xmlns:xacro="http://ros.org/wiki/xacro">

  <!-- Base link -->
  <link name="base_link">
    <visual>
      <geometry>
        <box size="0.4 0.3 0.1"/>
      </geometry>
      <origin xyz="0 0 0.05"/>
      <material name="base_material">
        <color rgba="0.5 0.5 0.5 1.0"/>
      </material>
    </visual>
    <!-- Inertial properties for base link -->
    <inertial>
      <mass value="1.0"/>  <!-- Adjust mass as needed -->
      <inertia ixx="0.01" ixy="0.0" ixz="0.0" iyy="0.01" iyz="0.0" izz="0.01"/>
    </inertial>
  </link>

  <!-- Wheels -->
  <link name="left_wheel">
    <visual>
      <geometry>
        <cylinder length="0.05" radius="0.05"/>
      </geometry>
      <origin xyz="0 0 0" rpy="0 0 0"/>
      <material name="wheel_material">
        <color rgba="0.2 0.2 0.2 1.0"/>
      </material>
    </visual>
    <!-- Inertial properties for left wheel -->
    <inertial>
      <mass value="0.1"/>  <!-- Adjust mass as needed -->
      <inertia ixx="0.0001" ixy="0.0" ixz="0.0" iyy="0.0001" iyz="0.0" izz="0.0001"/>
    </inertial>
  </link>

  <link name="right_wheel">
    <visual>
      <geometry>
        <cylinder length="0.05" radius="0.05"/>
      </geometry>
      <origin xyz="0 0 0" rpy="0 0 0"/>
      <material name="wheel_material">
        <color rgba="0.2 0.2 0.2 1.0"/>
      </material>
    </visual>
    <!-- Inertial properties for right wheel -->
    <inertial>
      <mass value="0.1"/>  <!-- Adjust mass as needed -->
      <inertia ixx="0.0001" ixy="0.0" ixz="0.0" iyy="0.0001" iyz="0.0" izz="0.0001"/>
    </inertial>
  </link>

  <!-- Joints for Wheels -->
  <joint name="left_wheel_joint" type="continuous">
    <parent link="base_link"/>
    <child link="left_wheel"/>
    <origin xyz="-0.2 0.15 0.05" rpy="0 0 0"/>
    <axis xyz="0 1 0"/>
  </joint>

  <joint name="right_wheel_joint" type="continuous">
    <parent link="base_link"/>
    <child link="right_wheel"/>
    <origin xyz="-0.2 -0.15 0.05" rpy="0 0 0"/>
    <axis xyz="0 1 0"/>
  </joint>

  <!-- Depth Camera -->
  <link name="depth_camera">
    <visual>
      <geometry>
        <box size="0.1 0.05 0.05"/>
      </geometry>
      <origin xyz="0 0 0"/>
      <material name="camera_material">
        <color rgba="0.2 0.2 0.8 1"/>
      </material>
    </visual>
    <!-- Inertial properties for depth camera -->
    <inertial>
      <mass value="0.05"/>  <!-- Adjust mass as needed -->
      <inertia ixx="0.0001" ixy="0.0" ixz="0.0" iyy="0.0001" iyz="0.0" izz="0.0001"/>
    </inertial>
  </link>

  <joint name="depth_camera_joint" type="fixed">
    <parent link="base_link"/>
    <child link="depth_camera"/>
    <origin xyz="0.0 0.0 0.15" rpy="0 0 0"/>
  </joint>

  <!-- Gazebo Plugins -->
  <gazebo>
    <!-- Depth Camera -->
    <sensor type="camera" name="depth_camera_sensor">
      <update_rate>30</update_rate>
      <camera>
        <horizontal_fov>1.047</horizontal_fov>
        <image>
          <width>640</width>
          <height>480</height>
          <format>R8G8B8</format>
        </image>
        <clip>
          <near>0.01</near>
          <far>5</far>
        </clip>
      </camera>
      <plugin name="gazebo_ros_realsense" filename="libgazebo_ros_camera.so">
        <always_on>true</always_on>
        <update_rate>30</update_rate>
        <camera_name>realsense_d435</camera_name>
      </plugin>
    </sensor>
  </gazebo>

  <!-- Differential Drive Plugin -->
  <gazebo>
    <plugin name="diff_drive_controller" filename="libgazebo_ros_diff_drive.so">
      <robotNamespace>/</robotNamespace>
      <commandTopic>/cmd_vel</commandTopic>
      <odometryTopic>/odom</odometryTopic>
      <leftJoint>left_wheel_joint</leftJoint>
      <rightJoint>right_wheel_joint</rightJoint>
      <wheelSeparation>0.3</wheelSeparation>
      <wheelDiameter>0.1</wheelDiameter>
      <updateRate>100</updateRate>
    </plugin>
  </gazebo>

</robot>





